Workbook

Sheet Cover
B2: NUM — FINANCIAL MODEL
B3: AI Personal Concierge · Phuket pilot + multi-tenant scale
B5: Prepared by | C5: Lumi (Dre)
B6: Date | C6: 2026-05-26
B7: Version | C7: 1.0
B8: Currency | C8: USD
B9: Horizon | C9: 36 months — monthly Y1, quarterly Y2–Y3
B11: Color key
B12: Blue text | C12: Hardcoded input — change to flex scenarios
B13: Black text | C13: Formula / calculation
B14: Green text | C14: Cross-sheet link
B15: Yellow background | C15: Key assumption to revisit
B18: Tab guide
B19: Assumptions | C19: Drivers: tenant rollout, ARPU components, COGS rates, OpEx
B20: Pilot | C20: Phuket pilot month-1 economics (rides → scans → activations → revenue)
B21: Y1_Monthly | C21: Months 1–12, all revenue + cost lines monthly
B22: Y2_Y3_Quarterly | C22: Q5–Q12, multi-tenant scale-up
B23: PnL_Summary | C23: Three-year P&L roll-up + key ratios
B24: Cap_Table_Sketch | C24: Bootstrapped scenario vs. seed raise — informal

Sheet Assumptions
B2: DRIVERS & ASSUMPTIONS
B4: Tenant rollout
B5: New tenants added | C5: Y1 | D5: Y2 | E5: Y3
B6: Pilot tenants (free, partner-funded) | C6: 1 | D6: 0 | E6: 0
B7: Pro tenants (paid) | C7: 1 | D7: 3 | E7: 4
B8: Enterprise tenants | C8: 0 | D8: 0 | E8: 2
B9: Total tenants — end of period | C9: =C6+C7+C8 -> 2 | D9: =C9+D6+D7+D8 -> 5 | E9: =D9+E6+E7+E8 -> 11
B11: Per-tenant economics (Pro tier baseline)
B12: Setup fee (one-time, $) | C12: 5000
B13: Monthly platform fee ($/mo) | C13: 2500
B14: Included conversations / mo | C14: 5000
B15: Usage overage rate ($/conversation) | C15: 0.04
B16: Expected MAU per mature tenant | C16: 10000
B17: Avg msgs per active user / mo | C17: 35
B18: Bookings per MAU / mo (12% × $40 commission) | C18: 4.8
B19: Whale leads per MAU / mo (1% × $300) | C19: 3
B20: Merchant featured-listing revenue / mo (gross, per tenant) | C20: 7000
B21: NUM+ subscription take-rate | C21: 0.03
B22: NUM+ price ($/mo) | C22: 9.99
B23: Lumi rev-share — bookings | C23: 0.35
... B26: Lumi rev-share — NUM+ subs | C26: 1
B28: Pilot drivers (Phuket InCar)
B29: Vehicles in pilot | C29: 35
B30: Rides per vehicle per day | C30: 25
B31: Days in pilot month | C31: 30
B32: QR scan rate | C32: 0.08
B33: Activation rate (scanner → 1+ msg) | C33: 0.6
B34: Active rate (≥6 msgs) | C34: 0.7
B35: Booking conversion (% active) | C35: 0.12
B36: Avg booking commission ($) | C36: 40
B37: Whale-lead rate (% active) | C37: 0.035
B38: Avg whale-lead fee ($) | C38: 300
B39: Lumi rev-share — pilot bookings | C39: 0.5
B40: Lumi rev-share — pilot whale leads | C40: 0.3
B41: Pilot infra absorbed by Lumi ($) | C41: 2300
B43: COGS & OpEx
B44: Variable COGS per active user / mo ($) | C44: 0.64
B45: Fixed infra & tooling ($/mo, Y1) | C45: 800
B46: Fixed infra & tooling ($/mo, Y2) | C46: 1800
B47: Fixed infra & tooling ($/mo, Y3) | C47: 3500
...

Sheet Pilot
B2: PHUKET PILOT — MONTH 1 SNAPSHOT
B3: Funnel
B4: Vehicles | C4: =Assumptions!C29 -> 35
B5: Rides / vehicle / day | C5: =Assumptions!C30 -> 25
B6: Days in month | C6: =Assumptions!C31 -> 30
B7: Total rides | C7: =C4*C5*C6 -> 26250
B8: QR scan rate | C8: =Assumptions!C32 -> 0.08
B9: QR scans | C9: =C7*C8 -> 2100
B10: Activation rate | C10: =Assumptions!C33 -> 0.6
B11: Activated users (sent ≥1 msg) | C11: =C9*C10 -> 1260
B12: Active rate (≥6 msgs) | C12: =Assumptions!C34 -> 0.7
B13: Active users | C13: =C11*C12 -> 882
B14: Revenue
B15: Booking conversion (% of active) | C15: =Assumptions!C35 -> 0.12
B16: Bookings | C16: =C13*C15 -> 105.84
B17: Avg booking commission | C17: =Assumptions!C36 -> 40
B18: Gross booking commissions | C18: =C16*C17 -> 4233.6
B19: Whale-lead rate (% of active) | C19: =Assumptions!C37 -> 0.035
B20: Qualified whale leads | C20: =C13*C19 -> 30.87
B21: Avg whale-lead fee | C21: =Assumptions!C38 -> 300
B22: Gross whale-lead revenue | C22: =C20*C21 -> 9261
B23: Gross pilot revenue | C23: =C18+C22 -> 13494.6
B25: Split
B26: Lumi share of bookings | C26: =Assumptions!C39*C18 -> 2116.8
B27: Lumi share of whale leads | C27: =Assumptions!C40*C22 -> 2778.3
B28: Lumi gross pilot revenue | C28: =C26+C27 -> 4895.1
B29: Pilot infra absorbed by Lumi | C29: =Assumptions!C41 -> 2300
B30: Lumi net (pilot, month 1) | C30: =C28-C29 -> 2595.1
B31: Partner share | C31: =C23-C28 -> 8599.5

Sheet Y1_Monthly
B2: YEAR 1 — MONTHLY P&L
C4: M1 | D4: M2 | E4: M3 | F4: M4 | G4: M5 | H4: M6 | I4: M7 | J4: M8 | K4: M9 | L4: M10 | M4: M11 | N4: M12 | O4: Y1 Total
B5: Tenants
B6: Pilot tenants (active) | C6: 1 | D6: 1 | E6: 0 | F6: 0 | G6: 0 | H6: 0 | I6: 0 | J6: 0 | K6: 0 | L6: 0 | M6: 0 | N6: 0
B7: Pro tenants (active) | C7: 0 | D7: 0 | E7: 1 | F7: 1 | G7: 1 | H7: 1 | I7: 1 | J7: 1 | K7: 1 | L7: 1 | M7: 2 | N7: 2
B8: MAU per Pro tenant (avg) | C8: 0 | D8: 0 | E8: 500 | F8: 1200 | G8: 2200 | H8: 3300 | I8: 4500 | J8: 5800 | K8: 7000 | L8: 8200 | M8: 9100 | N8: 10000
B9: Total active users | C9: =C7*C8 -> 0 | D9: =D7*D8 -> 0 | E9: =E7*E8 -> 500 | F9: =F7*F8 -> 1200 | G9: =G7*G8 -> 2200 | H9: =H7*H8 -> 3300 | I9: =I7*I8 -> 4500 | J9: =J7*J8 -> 5800 | ... N9: =N7*N8 -> 20000 | O9: =SUM(C9:N9) -> 70900
B11: Revenue ($)
B12: Platform fee (Pro) | C12: =C7*Assumptions!$C$13 -> 0 | D12: =D7*Assumptions!$C$13 -> 0 | E12: =E7*Assumptions!$C$13 -> 2500 | F12: =F7*Assumptions!$C$13 -> 2500 | G12: =G7*Assumptions!$C$13 -> 2500 | H12: =H7*Assumptions!$C$13 -> 2500 | I12: =I7*Assumptions!$C$13 -> 2500 | J12: =J7*Assumptions!$C$13 -> 2500 | ... N12: =N7*Assumptions!$C$13 -> 5000 | O12: =SUM(C12:N12) -> 30000
B13: Setup fees (one-time) | C13: 0 | D13: 0 | E13: 5000 | F13: 0 | G13: 0 | H13: 0 | I13: 0 | J13: 0 | K13: 0 | L13: 0 | M13: 5000 | N13: 0 | O13: =SUM(C13:N13) -> 10000
B14: Booking commissions (Lumi share) | C14: =C9*Assumptions!$C$18*Assumptions!$C$23 -> 0 | D14: =D9*Assumptions!$C$18*Assumptions!$C$23 -> 0 | E14: =E9*Assumptions!$C$18*Assumptions!$C$23 -> 840 | F14: =F9*Assumptions!$C$18*Assumptions!$C$23 -> 2016 | G14: =G9*Assumptions!$C$18*Assumptions!$C$23 -> 3696 | H14: =H9*Assumptions!$C$18*Assumptions!$C$23 -> 5544 | I14: =I9*Assumptions!$C$18*Assumptions!$C$23 -> 7560 | J14: =J9*Assumptions!$C$18*Assumptions!$C$23 -> 9744 | ... N14: =N9*Assumptions!$C$18*Assumptions!$C$23 -> 33600 | O14: =SUM(C14:N14) -> 119112
B15: Whale-lead revenue (Lumi share) | C15: =C9*Assumptions!$C$19*Assumptions!$C$24 -> 0 | D15: =D9*Assumptions!$C$19*Assumptions!$C$24 -> 0 | E15: =E9*Assumptions!$C$19*Assumptions!$C$24 -> 375 | F15: =F9*Assumptions!$C$19*Assumptions!$C$24 -> 900 | G15: =G9*Assumptions!$C$19*Assumptions!$C$24 -> 1650 | H15: =H9*Assumptions!$C$19*Assumptions!$C$24 -> 2475 | I15: =I9*Assumptions!$C$19*Assumptions!$C$24 -> 3375 | J15: =J9*Assumptions!$C$19*Assumptions!$C$24 -> 4350 | ... N15: =N9*Assumptions!$C$19*Assumptions!$C$24 -> 15000 | O15: =SUM(C15:N15) -> 53175
B16: Merchant featured-listing (Lumi share) | C16: =IF(C8>2000,C7*Assumptions!$C$20*Assumptions!$C$25,0) -> 0 | D16: =IF(D8>2000,D7*Assumptions!$C$20*Assumptions!$C$25,0) -> 0 | E16: =IF(E8>2000,E7*Assumptions!$C$20*Assumptions!$C$25,0) -> 0 | F16: =IF(F8>2000,F7*Assumptions!$C$20*Assumptions!$C$25,0) -> 0 | G16: =IF(G8>2000,G7*Assumptions!$C$20*Assumptions!$C$25,0) -> 2100 | H16: =IF(H8>2000,H7*Assumptions!$C$20*Assumptions!$C$25,0) -> 2100 | I16: =IF(I8>2000,I7*Assumptions!$C$20*Assumptions!$C$25,0) -> 2100 | J16: =IF(J8>2000,J7*Assumptions!$C$20*Assumptions!$C$25,0) -> 2100 | ... N16: =IF(N8>2000,N7*Assumptions!$C$20*Assumptions!$C$25,0) -> 4200 | O16: =SUM(C16:N16) -> 21000
B17: NUM+ subscriptions (Lumi share) | C17: =C9*Assumptions!$C$21*Assumptions!$C$22*Assumptions!$C$26 -> 0 | D17: =D9*Assumptions!$C$21*Assumptions!$C$22*Assumptions!$C$26 -> 0 | E17: =E9*Assumptions!$C$21*Assumptions!$C$22*Assumptions!$C$26 -> 149.85 | F17: =F9*Assumptions!$C$21*Assumptions!$C$22*Assumptions!$C$26 -> 359.64 | G17: =G9*Assumptions!$C$21*Assumptions!$C$22*Assumptions!$C$26 -> 659.34 | H17: =H9*Assumptions!$C$21*Assumptions!$C$22*Assumptions!$C$26 -> 989.01 | I17: =I9*Assumptions!$C$21*Assumptions!$C$22*Assumptions!$C$26 -> 1348.65 | J17: =J9*Assumptions!$C$21*Assumptions!$C$22*Assumptions!$C$26 -> 1738.26 | ... N17: =N9*Assumptions!$C$21*Assumptions!$C$22*Assumptions!$C$26 -> 5994 | O17: =SUM(C17:N17) -> 21248.73
B18: Pilot revenue (Lumi share, one-time) | C18: 4817 | D18: 0 | E18: 0 | F18: 0 | G18: 0 | H18: 0 | I18: 0 | J18: 0 | K18: 0 | L18: 0 | M18: 0 | N18: 0 | O18: =SUM(C18:N18) -> 4817
B19: Total revenue | C19: =SUM(C12:C18) -> 4817 | D19: =SUM(D12:D18) -> 0 | E19: =SUM(E12:E18) -> 8864.85 | F19: =SUM(F12:F18) -> 5775.64 | G19: =SUM(G12:G18) -> 10605.34 | H19: =SUM(H12:H18) -> 13608.01 | I19: =SUM(I12:I18) -> 16883.65 | J19: =SUM(J12:J18) -> 20432.26 | ... O19: =SUM(O12:O18) -> 259352.73
B21: COGS ($)
B22: Variable COGS (per-active) | C22: =C9*Assumptions!$C$44 -> 0 | D22: =D9*Assumptions!$C$44 -> 0 | E22: =E9*Assumptions!$C$44 -> 320 | F22: =F9*Assumptions!$C$44 -> 768 | G22: =G9*Assumptions!$C$44 -> 1408 | H22: =H9*Assumptions!$C$44 -> 2112 | I22: =I9*Assumptions!$C$44 -> 2880 | J22: =J9*Assumptions!$C$44 -> 3712 | ... N22: =N9*Assumptions!$C$44 -> 12800 | O22: =SUM(C22:N22) -> 45376
B23: Fixed infra & tooling | C23: =Assumptions!$C$45 -> 800 | D23: =Assumptions!$C$45 -> 800 | E23: =Assumptions!$C$45 -> 800 | F23: =Assumptions!$C$45 -> 800 | G23: =Assumptions!$C$45 -> 800 | H23: =Assumptions!$C$45 -> 800 | I23: =Assumptions!$C$45 -> 800 | J23: =Assumptions!$C$45 -> 800 | ... N23: =Assumptions!$C$45 -> 800 | O23: =SUM(C23:N23) -> 9600
B24: Total COGS | C24: =SUM(C22:C23) -> 800 | D24: =SUM(D22:D23) -> 800 | E24: =SUM(E22:E23) -> 1120 | F24: =SUM(F22:F23) -> 1568 | G24: =SUM(G22:G23) -> 2208 | H24: =SUM(H22:H23) -> 2912 | I24: =SUM(I22:I23) -> 3680 | J24: =SUM(J22:J23) -> 4512 | ... O24: =SUM(O22:O23) -> 54976
B25: Gross profit | C25: =C19-C24 -> 4017 | D25: =D19-D24 -> -800 | E25: =E19-E24 -> 7744.85 | F25: =F19-F24 -> 4207.64 | G25: =G19-G24 -> 8397.34 | H25: =H19-H24 -> 10696.01 | I25: =I19-I24 -> 13203.65 | J25: =J19-J24 -> 15920.26 | ... O25: =O19-O24 -> 204376.73
B26: Gross margin % | C26: =IFERROR(C25/C19,0) -> 0.83392153 | D26: =IFERROR(D25/D19,0) -> 0 | E26: =IFERROR(E25/E19,0) -> 0.87365832 | F26: =IFERROR(F25/F19,0) -> 0.72851494 | G26: =IFERROR(G25/G19,0) -> 0.791803 | H26: =IFERROR(H25/H19,0) -> 0.78600839 | I26: =IFERROR(I25/I19,0) -> 0.78203765 | J26: =IFERROR(J25/J19,0) -> 0.77917274 | ... O26: =IFERROR(O25/O19,0) -> 0.78802614
B28: OpEx ($)
B29: Headcount | C29: =Assumptions!$C$48 -> 12000 | D29: =Assumptions!$C$48 -> 12000 | E29: =Assumptions!$C$48 -> 12000 | F29: =Assumptions!$C$48 -> 12000 | G29: =Assumptions!$C$48 -> 12000 | H29: =Assumptions!$C$48 -> 12000 | I29: =Assumptions!$C$48 -> 12000 | J29: =Assumptions!$C$48 -> 12000 | ... N29: =Assumptions!$C$48 -> 12000 | O29: =SUM(C29:N29) -> 144000
B30: G&A + Tools | C30: =Assumptions!$C$51 -> 1500 | D30: =Assumptions!$C$51 -> 1500 | E30: =Assumptions!$C$51 -> 1500 | F30: =Assumptions!$C$51 -> 1500 | G30: =Assumptions!$C$51 -> 1500 | H30: =Assumptions!$C$51 -> 1500 | I30: =Assumptions!$C$51 -> 1500 | J30: =Assumptions!$C$51 -> 1500 | ... N30: =Assumptions!$C$51 -> 1500 | O30: =SUM(C30:N30) -> 18000
B31: Marketing | C31: =Assumptions!$C$54 -> 500 | D31: =Assumptions!$C$54 -> 500 | E31: =Assumptions!$C$54 -> 500 | F31: =Assumptions!$C$54 -> 500 | G31: =Assumptions!$C$54 -> 500 | H31: =Assumptions!$C$54 -> 500 | I31: =Assumptions!$C$54 -> 500 | J31: =Assumptions!$C$54 -> 500 | ... N31: =Assumptions!$C$54 -> 500 | O31: =SUM(C31:N31) -> 6000
B32: Total OpEx | C32: =SUM(C29:C31) -> 14000 | D32: =SUM(D29:D31) -> 14000 | E32: =SUM(E29:E31) -> 14000 | F32: =SUM(F29:F31) -> 14000 | G32: =SUM(G29:G31) -> 14000 | H32: =SUM(H29:H31) -> 14000 | I32: =SUM(I29:I31) -> 14000 | J32: =SUM(J29:J31) -> 14000 | ... O32: =SUM(O29:O31) -> 168000
B33: EBITDA | C33: =C25-C32 -> -9983 | D33: =D25-D32 -> -14800 | E33: =E25-E32 -> -6255.15 | F33: =F25-F32 -> -9792.36 | G33: =G25-G32 -> -5602.66 | H33: =H25-H32 -> -3303.99 | I33: =I25-I32 -> -796.35 | J33: =J25-J32 -> 1920.26 | ... O33: =O25-O32 -> 36376.73
B34: EBITDA margin % | C34: =IFERROR(C33/C19,0) -> -2.0724517 | D34: =IFERROR(D33/D19,0) -> 0 | E34: =IFERROR(E33/E19,0) -> -0.70561262 | F34: =IFERROR(F33/F19,0) -> -1.6954589 | G34: =IFERROR(G33/G19,0) -> -0.52828669 | H34: =IFERROR(H33/H19,0) -> -0.24279744 | I34: =IFERROR(I33/I19,0) -> -0.047166934 | J34: =IFERROR(J33/J19,0) -> 0.093981772 | ... O34: =IFERROR(O33/O19,0) -> 0.14025968
B36: Cumulative cash flow (no funding) | C36: =C33 -> -9983 | D36: =C36+D33 -> -24783 | E36: =D36+E33 -> -31038.15 | F36: =E36+F33 -> -40830.51 | G36: =F36+G33 -> -46433.17 | H36: =G36+H33 -> -49737.16 | I36: =H36+I33 -> -50533.51 | J36: =I36+J33 -> -48613.25 | K36: =J36+K33 -> -44185.35 | ... N36: =M36+N33 -> 36376.73 | O36: =N36 -> 36376.73

Sheet Y2_Y3_Quarterly
B2: YEARS 2–3 — QUARTERLY P&L
C4: Q5 | D4: Q6 | E4: Q7 | F4: Q8 | G4: Q9 | H4: Q10 | I4: Q11 | J4: Q12 | K4: Y2+Y3 Total
B5: Tenants
B6: Pro tenants (active) | C6: 2 | D6: 3 | E6: 4 | F6: 5 | G6: 6 | H6: 7 | I6: 8 | J6: 9
B7: Enterprise tenants (active) | C7: 0 | D7: 0 | E7: 0 | F7: 0 | G7: 0 | H7: 1 | I7: 1 | J7: 2
B8: MAU per Pro tenant (avg) | C8: 10000 | D8: 11000 | E8: 12500 | F8: 14000 | G8: 15500 | H8: 17000 | I8: 18500 | J8: 20000
B9: MAU per Enterprise tenant (avg) | C9: 0 | D9: 0 | E9: 0 | F9: 0 | G9: 0 | H9: 30000 | I9: 40000 | J9: 50000
B10: Total active users (per month avg in quarter) | C10: =C6*C8+C7*C9 -> 20000 | D10: =D6*D8+D7*D9 -> 33000 | E10: =E6*E8+E7*E9 -> 50000 | F10: =F6*F8+F7*F9 -> 70000 | G10: =G6*G8+G7*G9 -> 93000 | H10: =H6*H8+H7*H9 -> 149000 | I10: =I6*I8+I7*I9 -> 188000 | J10: =J6*J8+J7*J9 -> 280000
B12: Revenue ($/quarter)
B13: Platform fee (Pro+Ent) | C13: =3*(C6*Assumptions!$C$13 + C7*Assumptions!$C$13*4.5) -> 15000 | D13: =3*(D6*Assumptions!$C$13 + D7*Assumptions!$C$13*4.5) -> 22500 | E13: =3*(E6*Assumptions!$C$13 + E7*Assumptions!$C$13*4.5) -> 30000 | F13: =3*(F6*Assumptions!$C$13 + F7*Assumptions!$C$13*4.5) -> 37500 | G13: =3*(G6*Assumptions!$C$13 + G7*Assumptions!$C$13*4.5) -> 45000 | H13: =3*(H6*Assumptions!$C$13 + H7*Assumptions!$C$13*4.5) -> 86250 | I13: =3*(I6*Assumptions!$C$13 + I7*Assumptions!$C$13*4.5) -> 93750 | J13: =3*(J6*Assumptions!$C$13 + J7*Assumptions!$C$13*4.5) -> 135000 | K13: =SUM(C13:J13) -> 465000
B14: Setup fees (one-time) | C14: 5000 | D14: 5000 | E14: 5000 | F14: 5000 | G14: 5000 | H14: 30000 | I14: 5000 | J14: 30000 | K14: =SUM(C14:J14) -> 90000
B15: Booking commissions (Lumi share) | C15: =3*C10*Assumptions!$C$18*Assumptions!$C$23 -> 100800 | D15: =3*D10*Assumptions!$C$18*Assumptions!$C$23 -> 166320 | E15: =3*E10*Assumptions!$C$18*Assumptions!$C$23 -> 252000 | F15: =3*F10*Assumptions!$C$18*Assumptions!$C$23 -> 352800 | G15: =3*G10*Assumptions!$C$18*Assumptions!$C$23 -> 468720 | H15: =3*H10*Assumptions!$C$18*Assumptions!$C$23 -> 750960 | I15: =3*I10*Assumptions!$C$18*Assumptions!$C$23 -> 947520 | J15: =3*J10*Assumptions!$C$18*Assumptions!$C$23 -> 1411200 | K15: =SUM(C15:J15) -> 4450320
B16: Whale-lead revenue (Lumi share) | C16: =3*C10*Assumptions!$C$19*Assumptions!$C$24 -> 45000 | D16: =3*D10*Assumptions!$C$19*Assumptions!$C$24 -> 74250 | E16: =3*E10*Assumptions!$C$19*Assumptions!$C$24 -> 112500 | F16: =3*F10*Assumptions!$C$19*Assumptions!$C$24 -> 157500 | G16: =3*G10*Assumptions!$C$19*Assumptions!$C$24 -> 209250 | H16: =3*H10*Assumptions!$C$19*Assumptions!$C$24 -> 335250 | I16: =3*I10*Assumptions!$C$19*Assumptions!$C$24 -> 423000 | J16: =3*J10*Assumptions!$C$19*Assumptions!$C$24 -> 630000 | K16: =SUM(C16:J16) -> 1986750
B17: Merchant featured-listing (Lumi share) | C17: =3*(C6+C7)*Assumptions!$C$20*Assumptions!$C$25 -> 12600 | D17: =3*(D6+D7)*Assumptions!$C$20*Assumptions!$C$25 -> 18900 | E17: =3*(E6+E7)*Assumptions!$C$20*Assumptions!$C$25 -> 25200 | F17: =3*(F6+F7)*Assumptions!$C$20*Assumptions!$C$25 -> 31500 | G17: =3*(G6+G7)*Assumptions!$C$20*Assumptions!$C$25 -> 37800 | H17: =3*(H6+H7)*Assumptions!$C$20*Assumptions!$C$25 -> 50400 | I17: =3*(I6+I7)*Assumptions!$C$20*Assumptions!$C$25 -> 56700 | J17: =3*(J6+J7)*Assumptions!$C$20*Assumptions!$C$25 -> 69300 | K17: =SUM(C17:J17) -> 302400
B18: NUM+ subscriptions | C18: =3*C10*Assumptions!$C$21*Assumptions!$C$22*Assumptions!$C$26 -> 17982 | D18: =3*D10*Assumptions!$C$21*Assumptions!$C$22*Assumptions!$C$26 -> 29670.3 | E18: =3*E10*Assumptions!$C$21*Assumptions!$C$22*Assumptions!$C$26 -> 44955 | F18: =3*F10*Assumptions!$C$21*Assumptions!$C$22*Assumptions!$C$26 -> 62937 | G18: =3*G10*Assumptions!$C$21*Assumptions!$C$22*Assumptions!$C$26 -> 83616.3 | H18: =3*H10*Assumptions!$C$21*Assumptions!$C$22*Assumptions!$C$26 -> 133965.9 | I18: =3*I10*Assumptions!$C$21*Assumptions!$C$22*Assumptions!$C$26 -> 169030.8 | J18: =3*J10*Assumptions!$C$21*Assumptions!$C$22*Assumptions!$C$26 -> 251748 | K18: =SUM(C18:J18) -> 793905.3
B19: Total revenue | C19: =SUM(C13:C18) -> 196382 | D19: =SUM(D13:D18) -> 316640.3 | E19: =SUM(E13:E18) -> 469655 | F19: =SUM(F13:F18) -> 647237 | G19: =SUM(G13:G18) -> 849386.3 | H19: =SUM(H13:H18) -> 1386825.9 | I19: =SUM(I13:I18) -> 1695000.8 | J19: =SUM(J13:J18) -> 2527248 | K19: =SUM(K13:K18) -> 8088375.3
B21: COGS ($/quarter)
B22: Variable COGS | C22: =3*C10*Assumptions!$C$44 -> 38400 | D22: =3*D10*Assumptions!$C$44 -> 63360 | E22: =3*E10*Assumptions!$C$44 -> 96000 | F22: =3*F10*Assumptions!$C$44 -> 134400 | G22: =3*G10*Assumptions!$C$44 -> 178560 | H22: =3*H10*Assumptions!$C$44 -> 286080 | I22: =3*I10*Assumptions!$C$44 -> 360960 | J22: =3*J10*Assumptions!$C$44 -> 537600 | K22: =SUM(C22:J22) -> 1695360
B23: Fixed infra & tooling | C23: =3*Assumptions!$C$46 -> 5400 | D23: =3*Assumptions!$C$46 -> 5400 | E23: =3*Assumptions!$C$46 -> 5400 | F23: =3*Assumptions!$C$46 -> 5400 | G23: =3*Assumptions!$C$47 -> 10500 | H23: =3*Assumptions!$C$47 -> 10500 | I23: =3*Assumptions!$C$47 -> 10500 | J23: =3*Assumptions!$C$47 -> 10500 | K23: =SUM(C23:J23) -> 63600
B24: Total COGS | C24: =SUM(C22:C23) -> 43800 | D24: =SUM(D22:D23) -> 68760 | E24: =SUM(E22:E23) -> 101400 | F24: =SUM(F22:F23) -> 139800 | G24: =SUM(G22:G23) -> 189060 | H24: =SUM(H22:H23) -> 296580 | I24: =SUM(I22:I23) -> 371460 | J24: =SUM(J22:J23) -> 548100 | K24: =SUM(K22:K23) -> 1758960
B25: Gross profit | C25: =C19-C24 -> 152582 | D25: =D19-D24 -> 247880.3 | E25: =E19-E24 -> 368255 | F25: =F19-F24 -> 507437 | G25: =G19-G24 -> 660326.3 | H25: =H19-H24 -> 1090245.9 | I25: =I19-I24 -> 1323540.8 | J25: =J19-J24 -> 1979148 | K25: =K19-K24 -> 6329415.3
B26: Gross margin % | C26: =IFERROR(C25/C19,0) -> 0.7769653 | D26: =IFERROR(D25/D19,0) -> 0.78284508 | E26: =IFERROR(E25/E19,0) -> 0.78409684 | F26: =IFERROR(F25/F19,0) -> 0.78400493 | G26: =IFERROR(G25/G19,0) -> 0.77741576 | H26: =IFERROR(H25/H19,0) -> 0.78614475 | I26: =IFERROR(I25/I19,0) -> 0.78084966 | J26: =IFERROR(J25/J19,0) -> 0.78312378 | K26: =IFERROR(K25/K19,0) -> 0.78253235
B28: OpEx ($/quarter)
B29: Headcount | C29: =3*Assumptions!$C$49 -> 96000 | D29: =3*Assumptions!$C$49 -> 96000 | E29: =3*Assumptions!$C$49 -> 96000 | F29: =3*Assumptions!$C$49 -> 96000 | G29: =3*Assumptions!$C$50 -> 195000 | H29: =3*Assumptions!$C$50 -> 195000 | I29: =3*Assumptions!$C$50 -> 195000 | J29: =3*Assumptions!$C$50 -> 195000 | K29: =SUM(C29:J29) -> 1164000
B30: G&A + Tools | C30: =3*Assumptions!$C$52 -> 10500 | D30: =3*Assumptions!$C$52 -> 10500 | E30: =3*Assumptions!$C$52 -> 10500 | F30: =3*Assumptions!$C$52 -> 10500 | G30: =3*Assumptions!$C$53 -> 21000 | H30: =3*Assumptions!$C$53 -> 21000 | I30: =3*Assumptions!$C$53 -> 21000 | J30: =3*Assumptions!$C$53 -> 21000 | K30: =SUM(C30:J30) -> 126000
B31: Marketing | C31: =3*Assumptions!$C$55 -> 12000 | D31: =3*Assumptions!$C$55 -> 12000 | E31: =3*Assumptions!$C$55 -> 12000 | F31: =3*Assumptions!$C$55 -> 12000 | G31: =3*Assumptions!$C$56 -> 30000 | H31: =3*Assumptions!$C$56 -> 30000 | I31: =3*Assumptions!$C$56 -> 30000 | J31: =3*Assumptions!$C$56 -> 30000 | K31: =SUM(C31:J31) -> 168000
B32: Total OpEx | C32: =SUM(C29:C31) -> 118500 | D32: =SUM(D29:D31) -> 118500 | E32: =SUM(E29:E31) -> 118500 | F32: =SUM(F29:F31) -> 118500 | G32: =SUM(G29:G31) -> 246000 | H32: =SUM(H29:H31) -> 246000 | I32: =SUM(I29:I31) -> 246000 | J32: =SUM(J29:J31) -> 246000 | K32: =SUM(K29:K31) -> 1458000
B33: EBITDA | C33: =C25-C32 -> 34082 | D33: =D25-D32 -> 129380.3 | E33: =E25-E32 -> 249755 | F33: =F25-F32 -> 388937 | G33: =G25-G32 -> 414326.3 | H33: =H25-H32 -> 844245.9 | I33: =I25-I32 -> 1077540.8 | J33: =J25-J32 -> 1733148 | K33: =K25-K32 -> 4871415.3
B34: EBITDA margin % | C34: =IFERROR(C33/C19,0) -> 0.17354951 | D34: =IFERROR(D33/D19,0) -> 0.40860339 | E34: =IFERROR(E33/E19,0) -> 0.53178397 | F34: =IFERROR(F33/F19,0) -> 0.60091898 | G34: =IFERROR(G33/G19,0) -> 0.48779489 | H34: =IFERROR(H33/H19,0) -> 0.60876127 | I34: =IFERROR(I33/I19,0) -> 0.63571699 | J34: =IFERROR(J33/J19,0) -> 0.6857847 | K34: =IFERROR(K33/K19,0) -> 0.60227365
B36: Cumulative cash flow (from Y1 end) | C36: =Y1_Monthly!O36+C33 -> 70458.73 | D36: =C36+D33 -> 199839.03 | E36: =D36+E33 -> 449594.03 | F36: =E36+F33 -> 838531.03 | G36: =F36+G33 -> 1252857.3 | H36: =G36+H33 -> 2097103.2 | I36: =H36+I33 -> 3174644 | J36: =I36+J33 -> 4907792 | K36: =J36 -> 4907792

Sheet PnL_Summary
B2: 3-YEAR P&L SUMMARY
C4: Year 1 | D4: Year 2 | E4: Year 3 | F4: 3-Yr Total
B5: Revenue
B6: Platform fees + setup | C6: =Y1_Monthly!O12+Y1_Monthly!O13 -> 40000 | D6: =SUM(Y2_Y3_Quarterly!C13:F13)+SUM(Y2_Y3_Quarterly!C14:F14) -> 125000 | E6: =SUM(Y2_Y3_Quarterly!G13:J13)+SUM(Y2_Y3_Quarterly!G14:J14) -> 430000 | F6: =SUM(C6:E6) -> 595000
B7: Booking commissions | C7: =Y1_Monthly!O14+Y1_Monthly!O18 -> 123929 | D7: =SUM(Y2_Y3_Quarterly!C15:F15) -> 871920 | E7: =SUM(Y2_Y3_Quarterly!G15:J15) -> 3578400 | F7: =SUM(C7:E7) -> 4574249
B8: Whale-lead revenue | C8: =Y1_Monthly!O15 -> 53175 | D8: =SUM(Y2_Y3_Quarterly!C16:F16) -> 389250 | E8: =SUM(Y2_Y3_Quarterly!G16:J16) -> 1597500 | F8: =SUM(C8:E8) -> 2039925
B9: Merchant featured-listing | C9: =Y1_Monthly!O16 -> 21000 | D9: =SUM(Y2_Y3_Quarterly!C17:F17) -> 88200 | E9: =SUM(Y2_Y3_Quarterly!G17:J17) -> 214200 | F9: =SUM(C9:E9) -> 323400
B10: NUM+ subscriptions | C10: =Y1_Monthly!O17 -> 21248.73 | D10: =SUM(Y2_Y3_Quarterly!C18:F18) -> 155544.3 | E10: =SUM(Y2_Y3_Quarterly!G18:J18) -> 638361 | F10: =SUM(C10:E10) -> 815154.03
B11: Total revenue | C11: =SUM(C6:C10) -> 259352.73 | D11: =SUM(D6:D10) -> 1629914.3 | E11: =SUM(E6:E10) -> 6458461 | F11: =SUM(F6:F10) -> 8347728
B13: Total COGS | C13: =Y1_Monthly!O24 -> 54976 | D13: =SUM(Y2_Y3_Quarterly!C24:F24) -> 353760 | E13: =SUM(Y2_Y3_Quarterly!G24:J24) -> 1405200 | F13: =SUM(C13:E13) -> 1813936
B14: Gross profit | C14: =C11-C13 -> 204376.73 | D14: =D11-D13 -> 1276154.3 | E14: =E11-E13 -> 5053261 | F14: =F11-F13 -> 6533792
B15: Gross margin % | C15: =IFERROR(C14/C11,0) -> 0.78802614 | D15: =IFERROR(D14/D11,0) -> 0.78295791 | E15: =IFERROR(E14/E11,0) -> 0.78242495 | F15: =IFERROR(F14/F11,0) -> 0.78270303
B17: Total OpEx | C17: =Y1_Monthly!O32 -> 168000 | D17: =SUM(Y2_Y3_Quarterly!C32:F32) -> 474000 | E17: =SUM(Y2_Y3_Quarterly!G32:J32) -> 984000 | F17: =SUM(C17:E17) -> 1626000
B19: EBITDA | C19: =C14-C17 -> 36376.73 | D19: =D14-D17 -> 802154.3 | E19: =E14-E17 -> 4069261 | F19: =F14-F17 -> 4907792
B20: EBITDA margin % | C20: =IFERROR(C19/C11,0) -> 0.14025968 | D20: =IFERROR(D19/D11,0) -> 0.49214508 | E20: =IFERROR(E19/E11,0) -> 0.63006667 | F20: =IFERROR(F19/F11,0) -> 0.58791949
B22: Key ratios
B23: Tenants — end of period | C23: =Assumptions!C9 -> 2 | D23: =Assumptions!D9 -> 5 | E23: =Assumptions!E9 -> 11 | F23: =E23 -> 11
B24: Total active users (avg) | C24: =Y1_Monthly!O9/12 -> 5908.3333 | D24: =AVERAGE(Y2_Y3_Quarterly!C10:F10) -> 43250 | E24: =AVERAGE(Y2_Y3_Quarterly!G10:J10) -> 177500 | F24: =E24 -> 177500
B25: Revenue per active user (annual avg, $) | C25: =IFERROR(C11/(C24*12),0) -> 3.6580075 | D25: =IFERROR(D11/(D24*12),0) -> 3.14049 | E25: =IFERROR(E11/(E24*12),0) -> 3.0321413
B26: Revenue per tenant ($) | C26: =IFERROR(C11/C23,0) -> 129676.37 | D26: =IFERROR(D11/D23,0) -> 325982.86 | E26: =IFERROR(E11/E23,0) -> 587132.82

Sheet Cap_Table_Sketch
B2: FUNDING SCENARIOS — INFORMAL
B4: Scenario A — Bootstrapped (recommended)
B5: Capital required (Y1 burn coverage from founder + partner pilot) | C5: 60000
B6: Equity given up | C6: 0
B7: Founder ownership | C7: 1
B8: Path to profitability | C8: Q5–Q6 (early Y2)
B9: Implied Y3 valuation @ 5x revenue | C9: =PnL_Summary!E11*5 -> 32292305
B11: Scenario B — Seed raise (only if competitive heat demands it)
B12: Raise amount | C12: 750000
B13: Pre-money valuation | C13: 4000000
B14: Post-money | C14: =C12+C13 -> 4750000
B15: Dilution to founders | C15: =C12/C14 -> 0.15789474
B16: Use of funds — accelerate to 3 tenants in Y1 instead of 2
B17: Implied Y3 valuation @ 5x revenue | C17: =PnL_Summary!E11*5*1.4 -> 45209227
B18: Note: assumes funded scenario grows revenue 40% faster than bootstrapped
